#VRML_SIM R2023b utf8
PROTO FourWheelsRobot[

    field SFVec3f    translation  0 0 0
    field SFRotation rotation     0 0 1 0
    field SFFloat    bodyMass     1


]
{
  Robot {
  translation IS translation
  rotation IS rotation
  children [
    DistanceSensor {
      translation 0.1 -0.03 0
      rotation 0 0 1 -0.3
      children [
        DEF Ojito Shape {
          appearance PBRAppearance {
            baseColor 0 0 1
          }
          geometry Box {
            size 0.01 0.01 0.01
          }
        }
      ]
      name "ds_right"
      boundingObject USE Ojito
      physics Physics {
      }
    }
    DistanceSensor {
      translation 0.1 0.03 0
      rotation 0 0 1 0.3
      children [
        Shape {
          appearance PBRAppearance {
            baseColor 0 0 1
          }
          geometry Box {
            size 0.01 0.01 0.01
          }
        }
      ]
      name "ds_left"
      boundingObject USE Ojito
      physics Physics {
      }
    }
    DEF cuerpo Shape {
      appearance PBRAppearance {
        baseColor 1 0 0
        metalness 0
      }
      geometry Box {
        size 0.2 0.1 0.05
      }
    }
    HingeJoint {
      jointParameters HingeJointParameters {
        axis 0 1 0
        anchor 0.05 0.06 0
      }
      device [
        RotationalMotor {
          name "wheel1"
        }
      ]
      endPoint Solid {
        translation 0.05 0.06 0
        rotation 1 0 0 1.5708
        children [
          DEF Rueda1 Shape {
            appearance PBRAppearance {
              baseColor 0 1 0
            }
            geometry Cylinder {
              height 0.02
              radius 0.04
            }
          }
        ]
        boundingObject USE Rueda1
        physics Physics {
        }
      }
    }
    HingeJoint {
      jointParameters HingeJointParameters {
        axis 0 1 0
        anchor 0.05 0.06 0
      }
      device [
        RotationalMotor {
          name "wheel2"
        }
      ]
      endPoint Solid {
        translation 0.05 -0.06 0
        rotation 1 0 0 1.5708
        children [
          USE Rueda1
        ]
        name "solid(1)"
        boundingObject USE Rueda1
        physics Physics {
        }
      }
    }
    HingeJoint {
      jointParameters HingeJointParameters {
        axis 0 1 0
        anchor -0.05 0.06 0
      }
      device [
        RotationalMotor {
          name "wheel3"
        }
      ]
      endPoint Solid {
        translation -0.05000192442263276 0.060000048833835876 -2.849375532541905e-07
        rotation 0.9999999999999999 3.0438793541153723e-09 3.0438681279749124e-09 1.5708000003314428
        children [
          USE Rueda1
        ]
        name "solid(2)"
        boundingObject USE Rueda1
        physics Physics {
        }
      }
    }
    HingeJoint {
      jointParameters HingeJointParameters {
        axis 0 1 0
        anchor -0.05 -0.06 0
      }
      device [
        RotationalMotor {
          name "wheel4"
        }
      ]
      endPoint Solid {
        translation -0.0499974 -0.06 0
        rotation -1 8.678115109274295e-10 8.678083314960364e-10 4.712385309442199
        children [
          USE Rueda1
        ]
        name "solid(3)"
        boundingObject USE Rueda1
        physics Physics {
        }
      }
    }
  ]
  boundingObject USE cuerpo
  physics Physics {
    density -1
    mass IS  bodyMass
  }
  controller "four_wheeled_collision_avoidance"
    }
}
